<?xml version="1.0"?>
<robot name="mr_springs_fallback">
  <link name="world"/>
  <link name="chassis">
    <inertial>
      <mass value="1.0"/>
      <origin xyz="0 0 0"/>
      <inertia ixx="0.01" ixy="0" ixz="0.01" iyy="0.01" iyz="0" izz="0.01"/>
    </inertial>
    <visual><geometry><box size="0.2 0.2 0.2"/></geometry></visual>
    <collision><geometry><box size="0.2 0.2 0.2"/></geometry></collision>
  </link>
  <joint name="z_joint" type="prismatic">
    <parent link="world"/><child link="chassis"/>
    <axis xyz="0 0 1"/><limit lower="0" upper="5" effort="100" velocity="10"/>
  </joint>
</robot>
