<?xml version="1.0" ?>
<!-- =================================================================================== -->
<!-- |    This document was autogenerated by xacro from eecs4421_1d_hopper_wrapper.xacro | -->
<!-- |    EDITING THIS FILE BY HAND IS NOT RECOMMENDED                                 | -->
<!-- =================================================================================== -->
<robot name="eecs4421_1d_hopper">
  <material name="silver">
    <color rgba="0.700 0.700 0.700 1.000"/>
  </material>
  <!-- Note: .trans and .gazebo files are for ROS/Gazebo, not needed for PyBullet -->
  <link name="base_link">
    <inertial>
      <origin rpy="0 0 0" xyz="-0.013514090010165696 0.00024331067916718278 0.0690405797342188"/>
      <mass value="0.2824006607720704"/>
      <inertia ixx="0.001426" ixy="0.0" ixz="-5e-06" iyy="0.001359" iyz="0.0" izz="7.2e-05"/>
    </inertial>
    <visual>
      <origin rpy="0 0 0" xyz="0 0 0"/>
      <geometry>
        <mesh filename="meshes/base_link.stl" scale="0.001 0.001 0.001"/>
      </geometry>
      <material name="silver"/>
    </visual>
    <collision>
      <origin rpy="0 0 0" xyz="0 0 0"/>
      <geometry>
        <mesh filename="meshes/base_link.stl" scale="0.001 0.001 0.001"/>
      </geometry>
    </collision>
  </link>
  <link name="Spring_2_1_v1_1_1_1">
    <inertial>
      <origin rpy="0 0 0" xyz="2.9307851018650632e-05 -4.8964241178072604e-05 -0.08138700684547578"/>
      <mass value="0.012593013169921327"/>
      <inertia ixx="3.2e-05" ixy="0.0" ixz="-0.0" iyy="3.2e-05" iyz="0.0" izz="1e-06"/>
    </inertial>
    <visual>
      <origin rpy="0 0 0" xyz="0.013319 0.022758 -0.135804"/>
      <geometry>
        <mesh filename="meshes/Spring_2_1_v1_1_1_1.stl" scale="0.001 0.001 0.001"/>
      </geometry>
      <material name="silver"/>
    </visual>
    <collision>
      <origin rpy="0 0 0" xyz="0.013319 0.022758 -0.135804"/>
      <geometry>
        <mesh filename="meshes/Spring_2_1_v1_1_1_1.stl" scale="0.001 0.001 0.001"/>
      </geometry>
    </collision>
  </link>
  <link name="Spring_1_1_v1_1_1_1_1">
    <inertial>
      <origin rpy="0 0 0" xyz="-0.00010111466336726847 -1.1734179564099056e-05 -0.08138700684547563"/>
      <mass value="0.012593013169921313"/>
      <inertia ixx="3.2e-05" ixy="0.0" ixz="-0.0" iyy="3.2e-05" iyz="0.0" izz="1e-06"/>
    </inertial>
    <visual>
      <origin rpy="0 0 0" xyz="0.013319 -0.023242 -0.135804"/>
      <geometry>
        <mesh filename="meshes/Spring_1_1_v1_1_1_1_1.stl" scale="0.001 0.001 0.001"/>
      </geometry>
      <material name="silver"/>
    </visual>
    <collision>
      <origin rpy="0 0 0" xyz="0.013319 -0.023242 -0.135804"/>
      <geometry>
        <mesh filename="meshes/Spring_1_1_v1_1_1_1_1.stl" scale="0.001 0.001 0.001"/>
      </geometry>
    </collision>
  </link>
  <link name="5x63mm_Aluminium_Rod__2_1_v1_1">
    <inertial>
      <origin rpy="0 0 0" xyz="-3.6128128096460377e-07 0.03160000806298522 -3.623302492258146e-07"/>
      <mass value="0.009741293420618765"/>
      <inertia ixx="3e-06" ixy="-0.0" ixz="0.0" iyy="0.0" iyz="0.0" izz="3e-06"/>
    </inertial>
    <visual>
      <origin rpy="0 0 0" xyz="-0.014983 0.028358 0.013297"/>
      <geometry>
        <mesh filename="meshes/5x63mm_Aluminium_Rod__2_1_v1_1.stl" scale="0.001 0.001 0.001"/>
      </geometry>
      <material name="silver"/>
    </visual>
    <collision>
      <origin rpy="0 0 0" xyz="-0.014983 0.028358 0.013297"/>
      <geometry>
        <mesh filename="meshes/5x63mm_Aluminium_Rod__2_1_v1_1.stl" scale="0.001 0.001 0.001"/>
      </geometry>
    </collision>
  </link>
  <link name="motor_1_v1_1">
    <inertial>
      <origin rpy="0 0 0" xyz="-0.014789621893783248 0.003124183549591557 0.014757253552300956"/>
      <mass value="0.24917752024157286"/>
      <inertia ixx="5.5e-05" ixy="1e-06" ixz="1.4e-05" iyy="4.4e-05" iyz="-1e-06" izz="5.5e-05"/>
    </inertial>
    <visual>
      <origin rpy="0 0 0" xyz="-0.03902 0.013546 0.00552"/>
      <geometry>
        <mesh filename="meshes/motor_1_v1_1.stl" scale="0.001 0.001 0.001"/>
      </geometry>
      <material name="silver"/>
    </visual>
    <collision>
      <origin rpy="0 0 0" xyz="-0.03902 0.013546 0.00552"/>
      <geometry>
        <mesh filename="meshes/motor_1_v1_1.stl" scale="0.001 0.001 0.001"/>
      </geometry>
    </collision>
  </link>
  <link name="wheel_2_complete_1_v2_1">
    <inertial>
      <origin rpy="0 0 0" xyz="-3.3718511046375646e-06 -0.013584361592914915 6.754300349003789e-07"/>
      <mass value="0.14618559800198688"/>
      <inertia ixx="0.00019" ixy="-0.0" ixz="0.0" iyy="0.000375" iyz="0.0" izz="0.00019"/>
    </inertial>
    <visual>
      <origin rpy="0 0 0" xyz="0.006473 0.060708 0.008985"/>
      <geometry>
        <mesh filename="meshes/wheel_2_complete_1_v2_1.stl" scale="0.001 0.001 0.001"/>
      </geometry>
      <material name="silver"/>
    </visual>
    <collision>
      <origin rpy="0 0 0" xyz="0.006473 0.060708 0.008985"/>
      <geometry>
        <mesh filename="meshes/wheel_2_complete_1_v2_1.stl" scale="0.001 0.001 0.001"/>
      </geometry>
    </collision>
  </link>
  <link name="wheel_1_complete_1_v1_1">
    <inertial>
      <origin rpy="0 0 0" xyz="-3.3718467262128585e-06 0.013584378715335813 6.754317408552007e-07"/>
      <mass value="0.14618560543842687"/>
      <inertia ixx="0.00019" ixy="0.0" ixz="0.0" iyy="0.000375" iyz="-0.0" izz="0.00019"/>
    </inertial>
    <visual>
      <origin rpy="0 0 0" xyz="0.006473 -0.061292 0.008985"/>
      <geometry>
        <mesh filename="meshes/wheel_1_complete_1_v1_1.stl" scale="0.001 0.001 0.001"/>
      </geometry>
      <material name="silver"/>
    </visual>
    <collision>
      <origin rpy="0 0 0" xyz="0.006473 -0.061292 0.008985"/>
      <geometry>
        <mesh filename="meshes/wheel_1_complete_1_v1_1.stl" scale="0.001 0.001 0.001"/>
      </geometry>
    </collision>
  </link>
  <link name="Motor_1_1_v1_1">
    <inertial>
      <origin rpy="0 0 0" xyz="0.004996649817929426 -0.011974487243527066 -0.005999973775597767"/>
      <mass value="0.022989886144955934"/>
      <inertia ixx="2e-06" ixy="0.0" ixz="-0.0" iyy="0.0" iyz="-0.0" izz="1e-06"/>
    </inertial>
    <visual>
      <origin rpy="0 0 0" xyz="0.002382 -0.057202 -0.002506"/>
      <geometry>
        <mesh filename="meshes/Motor_1_1_v1_1.stl" scale="0.001 0.001 0.001"/>
      </geometry>
      <material name="silver"/>
    </visual>
    <collision>
      <origin rpy="0 0 0" xyz="0.002382 -0.057202 -0.002506"/>
      <geometry>
        <mesh filename="meshes/Motor_1_1_v1_1.stl" scale="0.001 0.001 0.001"/>
      </geometry>
    </collision>
  </link>
  <link name="Motor_2_1_v1_1">
    <inertial>
      <origin rpy="0 0 0" xyz="0.004996649817928127 0.01197450461385928 -0.005999973775597859"/>
      <mass value="0.022989886144955944"/>
      <inertia ixx="2e-06" ixy="-0.0" ixz="-0.0" iyy="0.0" iyz="0.0" izz="1e-06"/>
    </inertial>
    <visual>
      <origin rpy="0 0 0" xyz="0.002382 0.056758 -0.002506"/>
      <geometry>
        <mesh filename="meshes/Motor_2_1_v1_1.stl" scale="0.001 0.001 0.001"/>
      </geometry>
      <material name="silver"/>
    </visual>
    <collision>
      <origin rpy="0 0 0" xyz="0.002382 0.056758 -0.002506"/>
      <geometry>
        <mesh filename="meshes/Motor_2_1_v1_1.stl" scale="0.001 0.001 0.001"/>
      </geometry>
    </collision>
  </link>
  <link name="Motor_Gear_1_1_v1_1">
    <inertial>
      <origin rpy="0 0 0" xyz="1.8784622158076348e-05 0.0035000093073439473 -3.869260724927853e-08"/>
      <mass value="0.002745880235689738"/>
      <inertia ixx="0.0" ixy="0.0" ixz="0.0" iyy="0.0" iyz="0.0" izz="0.0"/>
    </inertial>
    <visual>
      <origin rpy="0 0 0" xyz="-0.002573 -0.060202 0.003523"/>
      <geometry>
        <mesh filename="meshes/Motor_Gear_1_1_v1_1.stl" scale="0.001 0.001 0.001"/>
      </geometry>
      <material name="silver"/>
    </visual>
    <collision>
      <origin rpy="0 0 0" xyz="-0.002573 -0.060202 0.003523"/>
      <geometry>
        <mesh filename="meshes/Motor_Gear_1_1_v1_1.stl" scale="0.001 0.001 0.001"/>
      </geometry>
    </collision>
  </link>
  <link name="Second_Gear_1_v1_1">
    <inertial>
      <origin rpy="0 0 0" xyz="-3.611020787941399e-10 -0.013996863973097079 -1.9367322502683582e-10"/>
      <mass value="0.12592322311736695"/>
      <inertia ixx="2.7e-05" ixy="0.0" ixz="0.0" iyy="1.4e-05" iyz="-0.0" izz="2.7e-05"/>
    </inertial>
    <visual>
      <origin rpy="0 0 0" xyz="-0.015 -0.027842 0.0133"/>
      <geometry>
        <mesh filename="meshes/Second_Gear_1_v1_1.stl" scale="0.001 0.001 0.001"/>
      </geometry>
      <material name="silver"/>
    </visual>
    <collision>
      <origin rpy="0 0 0" xyz="-0.015 -0.027842 0.0133"/>
      <geometry>
        <mesh filename="meshes/Second_Gear_1_v1_1.stl" scale="0.001 0.001 0.001"/>
      </geometry>
    </collision>
  </link>
  <link name="Motor_Gear_2_1_v1_1">
    <inertial>
      <origin rpy="0 0 0" xyz="1.8936466043807058e-05 -0.0034999919370117746 6.437635519541268e-08"/>
      <mass value="0.002745880235689775"/>
      <inertia ixx="0.0" ixy="-0.0" ixz="0.0" iyy="0.0" iyz="0.0" izz="0.0"/>
    </inertial>
    <visual>
      <origin rpy="0 0 0" xyz="-0.002571 0.059758 0.003498"/>
      <geometry>
        <mesh filename="meshes/Motor_Gear_2_1_v1_1.stl" scale="0.001 0.001 0.001"/>
      </geometry>
      <material name="silver"/>
    </visual>
    <collision>
      <origin rpy="0 0 0" xyz="-0.002571 0.059758 0.003498"/>
      <geometry>
        <mesh filename="meshes/Motor_Gear_2_1_v1_1.stl" scale="0.001 0.001 0.001"/>
      </geometry>
    </collision>
  </link>
  <link name="2S_LiPo_1_v1_1">
    <inertial>
      <origin rpy="0 0 0" xyz="-0.006999631251769917 8.692172037070818e-09 -6.845474279440489e-09"/>
      <mass value="0.17561484928297033"/>
      <inertia ixx="5.6e-05" ixy="-0.0" ixz="-0.0" iyy="4.6e-05" iyz="0.0" izz="1.5e-05"/>
    </inertial>
    <visual>
      <origin rpy="0 0 0" xyz="0.025319 -0.000242 -0.004004"/>
      <geometry>
        <mesh filename="meshes/2S_LiPo_1_v1_1.stl" scale="0.001 0.001 0.001"/>
      </geometry>
      <material name="silver"/>
    </visual>
    <collision>
      <origin rpy="0 0 0" xyz="0.025319 -0.000242 -0.004004"/>
      <geometry>
        <mesh filename="meshes/2S_LiPo_1_v1_1.stl" scale="0.001 0.001 0.001"/>
      </geometry>
    </collision>
  </link>
  <link name="moving_frame_1_v1_1">
    <inertial>
      <origin rpy="0 0 0" xyz="0.013616715709348168 0.021707483601140144 0.02951565572802407"/>
      <mass value="0.4412684216504674"/>
      <inertia ixx="0.000588" ixy="1.7e-05" ixz="-3.8e-05" iyy="0.000281" iyz="1.8e-05" izz="0.000543"/>
    </inertial>
    <visual>
      <origin rpy="0 0 0" xyz="0.013319 0.022758 0.047996"/>
      <geometry>
        <mesh filename="meshes/moving_frame_1_v1_1.stl" scale="0.001 0.001 0.001"/>
      </geometry>
      <material name="silver"/>
    </visual>
    <collision>
      <origin rpy="0 0 0" xyz="0.013319 0.022758 0.047996"/>
      <geometry>
        <mesh filename="meshes/moving_frame_1_v1_1.stl" scale="0.001 0.001 0.001"/>
      </geometry>
    </collision>
  </link>
  <link name="Main_Gear_1_v1_1">
    <inertial>
      <origin rpy="0 0 0" xyz="0.0006468404293882742 -0.015599991892107774 0.0003664112445932455"/>
      <mass value="0.2816436332857111"/>
      <inertia ixx="5.2e-05" ixy="0.0" ixz="1e-06" iyy="5.5e-05" iyz="0.0" izz="5e-05"/>
    </inertial>
    <visual>
      <origin rpy="0 0 0" xyz="-0.009058 -0.015842 0.042609"/>
      <geometry>
        <mesh filename="meshes/Main_Gear_1_v1_1.stl" scale="0.001 0.001 0.001"/>
      </geometry>
      <material name="silver"/>
    </visual>
    <collision>
      <origin rpy="0 0 0" xyz="-0.009058 -0.015842 0.042609"/>
      <geometry>
        <mesh filename="meshes/Main_Gear_1_v1_1.stl" scale="0.001 0.001 0.001"/>
      </geometry>
    </collision>
  </link>
  <link name="5x63mm_Aluminium_Rod__1_1_v1_1">
    <inertial>
      <origin rpy="0 0 0" xyz="3.687482312830781e-07 0.03160000806298602 -6.8453424872938484e-09"/>
      <mass value="0.009741293420618774"/>
      <inertia ixx="3e-06" ixy="-0.0" ixz="0.0" iyy="0.0" iyz="-0.0" izz="3e-06"/>
    </inertial>
    <visual>
      <origin rpy="0 0 0" xyz="-0.008981 0.028358 0.042496"/>
      <geometry>
        <mesh filename="meshes/5x63mm_Aluminium_Rod__1_1_v1_1.stl" scale="0.001 0.001 0.001"/>
      </geometry>
      <material name="silver"/>
    </visual>
    <collision>
      <origin rpy="0 0 0" xyz="-0.008981 0.028358 0.042496"/>
      <geometry>
        <mesh filename="meshes/5x63mm_Aluminium_Rod__1_1_v1_1.stl" scale="0.001 0.001 0.001"/>
      </geometry>
    </collision>
  </link>
  <link name="Servo_Gear_1_v1_1">
    <inertial>
      <origin rpy="0 0 0" xyz="1.5808685818741175e-09 -0.004999991936778844 1.045276603502121e-07"/>
      <mass value="0.033507073455686986"/>
      <inertia ixx="2e-06" ixy="-0.0" ixz="0.0" iyy="3e-06" iyz="0.0" izz="2e-06"/>
    </inertial>
    <visual>
      <origin rpy="0 0 0" xyz="-0.017412 -0.027842 -0.016062"/>
      <geometry>
        <mesh filename="meshes/Servo_Gear_1_v1_1.stl" scale="0.001 0.001 0.001"/>
      </geometry>
      <material name="silver"/>
    </visual>
    <collision>
      <origin rpy="0 0 0" xyz="-0.017412 -0.027842 -0.016062"/>
      <geometry>
        <mesh filename="meshes/Servo_Gear_1_v1_1.stl" scale="0.001 0.001 0.001"/>
      </geometry>
    </collision>
  </link>
  <link name="Servo_Pin_5x16mm_1_v1_1">
    <inertial>
      <origin rpy="0 0 0" xyz="3.991380445426962e-07 -0.007999991937014558 -6.481572515509848e-08"/>
      <mass value="0.0024661502330680964"/>
      <inertia ixx="0.0" ixy="-0.0" ixz="-0.0" iyy="0.0" iyz="-0.0" izz="0.0"/>
    </inertial>
    <visual>
      <origin rpy="0 0 0" xyz="-0.017409 -0.036842 -0.016098"/>
      <geometry>
        <mesh filename="meshes/Servo_Pin_5x16mm_1_v1_1.stl" scale="0.001 0.001 0.001"/>
      </geometry>
      <material name="silver"/>
    </visual>
    <collision>
      <origin rpy="0 0 0" xyz="-0.017409 -0.036842 -0.016098"/>
      <geometry>
        <mesh filename="meshes/Servo_Pin_5x16mm_1_v1_1.stl" scale="0.001 0.001 0.001"/>
      </geometry>
    </collision>
  </link>
  <joint name="spring_2_sliding" type="prismatic">
    <origin rpy="0 0 0" xyz="-0.013319 -0.022758 0.135804"/>
    <parent link="base_link"/>
    <child link="Spring_2_1_v1_1_1_1"/>
    <axis xyz="0.0 0.0 -1.0"/>
    <limit effort="100" lower="0.0" upper="0.015" velocity="100"/>
  </joint>
  <joint name="spring_1_sliding" type="prismatic">
    <origin rpy="0 0 0" xyz="-0.013319 0.023242 0.135804"/>
    <parent link="base_link"/>
    <child link="Spring_1_1_v1_1_1_1_1"/>
    <axis xyz="0.0 0.0 -1.0"/>
    <limit effort="100" lower="0.0" upper="0.015" velocity="100"/>
  </joint>
  <joint name="secondary_gear_axle_to_frame" type="fixed">
    <origin rpy="0 0 0" xyz="0.028302 -0.0056 0.034699"/>
    <parent link="moving_frame_1_v1_1"/>
    <child link="5x63mm_Aluminium_Rod__2_1_v1_1"/>
  </joint>
  <joint name="motor_to_frame" type="fixed">
    <origin rpy="0 0 0" xyz="0.052339 0.009212 0.042476"/>
    <parent link="moving_frame_1_v1_1"/>
    <child link="motor_1_v1_1"/>
  </joint>
  <joint name="wheel_2_to_frame" type="continuous">
    <origin rpy="0 0 0" xyz="0.006846 -0.03795 0.039011"/>
    <parent link="moving_frame_1_v1_1"/>
    <child link="wheel_2_complete_1_v2_1"/>
    <axis xyz="0.0 1.0 -0.0"/>
  </joint>
  <joint name="wheel_1_to_frame" type="continuous">
    <origin rpy="0 0 0" xyz="0.006846 0.08405 0.039011"/>
    <parent link="moving_frame_1_v1_1"/>
    <child link="wheel_1_complete_1_v1_1"/>
    <axis xyz="-0.0 -1.0 0.0"/>
  </joint>
  <joint name="motor_1_to_frame" type="fixed">
    <origin rpy="0 0 0" xyz="0.010937 0.07996 0.050502"/>
    <parent link="moving_frame_1_v1_1"/>
    <child link="Motor_1_1_v1_1"/>
  </joint>
  <joint name="motor_2_to_frame" type="fixed">
    <origin rpy="0 0 0" xyz="0.010937 -0.034 0.050502"/>
    <parent link="moving_frame_1_v1_1"/>
    <child link="Motor_2_1_v1_1"/>
  </joint>
  <joint name="motor_gear_1_revolution" type="continuous">
    <origin rpy="0 0 0" xyz="0.004955 0.003 -0.006029"/>
    <parent link="Motor_1_1_v1_1"/>
    <child link="Motor_Gear_1_1_v1_1"/>
    <axis xyz="0.0 1.0 0.0"/>
  </joint>
  <joint name="secondary_gear_revolution" type="continuous">
    <origin rpy="0 0 0" xyz="1.7e-05 0.0562 -3e-06"/>
    <parent link="5x63mm_Aluminium_Rod__2_1_v1_1"/>
    <child link="Second_Gear_1_v1_1"/>
    <axis xyz="0.0 1.0 0.0"/>
  </joint>
  <joint name="motor_gear_2_revolution" type="continuous">
    <origin rpy="0 0 0" xyz="0.004953 -0.003 -0.006004"/>
    <parent link="Motor_2_1_v1_1"/>
    <child link="Motor_Gear_2_1_v1_1"/>
    <axis xyz="-0.0 -1.0 -0.0"/>
  </joint>
  <joint name="lipo_to_frame" type="fixed">
    <origin rpy="0 0 0" xyz="-0.012 0.023 0.052"/>
    <parent link="moving_frame_1_v1_1"/>
    <child link="2S_LiPo_1_v1_1"/>
  </joint>
  <joint name="moving_frame_to_base_link" type="prismatic">
    <origin rpy="0 0 0" xyz="-0.013319 -0.022758 -0.047996"/>
    <parent link="base_link"/>
    <child link="moving_frame_1_v1_1"/>
    <axis xyz="-0.0 -0.0 1.0"/>
    <limit effort="100" lower="0.0" upper="0.139" velocity="100"/>
  </joint>
  <joint name="main_gear_revolution" type="continuous">
    <origin rpy="0 0 0" xyz="7.7e-05 0.0442 -0.000113"/>
    <parent link="5x63mm_Aluminium_Rod__1_1_v1_1"/>
    <child link="Main_Gear_1_v1_1"/>
    <axis xyz="0.0 1.0 0.0"/>
  </joint>
  <joint name="main_gear_axle_to_moving_frame" type="fixed">
    <origin rpy="0 0 0" xyz="0.0223 -0.0056 0.0055"/>
    <parent link="moving_frame_1_v1_1"/>
    <child link="5x63mm_Aluminium_Rod__1_1_v1_1"/>
  </joint>
  <joint name="servo_gear_revolution" type="continuous">
    <origin rpy="0 0 0" xyz="3e-06 -0.009 -3.6e-05"/>
    <parent link="Servo_Pin_5x16mm_1_v1_1"/>
    <child link="Servo_Gear_1_v1_1"/>
    <axis xyz="0.0 1.0 -0.0"/>
  </joint>
  <joint name="servo_pin_to_frame" type="fixed">
    <origin rpy="0 0 0" xyz="0.030728 0.0596 0.064094"/>
    <parent link="moving_frame_1_v1_1"/>
    <child link="Servo_Pin_5x16mm_1_v1_1"/>
  </joint>
  <!-- No world link - base_link is the root link and will be free in PyBullet -->
  <!-- 1D motion will be constrained via code using _clamp_to_1d() method -->
</robot>
